Workbook
Name Slicer_Discount_Category: #N/A
Name Slicer_Rating_Category: #N/A

Sheet Raw_Dataset
A1: Product | B1: Current price | C1: old price | D1: Discount | E1: Review | F1: Ratingd
A2: 115 Piece Set Of Multifunctional Precision Screwdrivers | B2: KSh 950 | C2: KSh 1,525 | D2: 0.38 | E2: -2 | F2: 4.5 out of 5
A3: Metal Decorative Hooks Key Hangers Entryway Wall Hooks Towel Hooks - Home | B3: KSh 527 | C3: KSh 999 | D3: 0.47 | E3: -14 | F3: 4.1 out of 5
A4: Portable Mini Cordless Car Vacuum Cleaner - Blue | B4: KSh 2,199 | C4: KSh 2,923 | D4: 0.25 | E4: -24 | F4: 4.6 out of 5
A5: Weighing Scale Digital Bathroom Body Fat Scale USB-Black | B5: KSh 1,580 | C5: KSh 2,499 | D5: 0.37 | E5: -7 | F5: 4.7 out of 5
A6: Portable Home Small Air Humidifier 3-Speed Fan - Green | B6: KSh 1,740 | C6: KSh 2,356 | D6: 0.26 | E6: -5 | F6: 4.8 out of 5
A7: 220V 60W Electric Soldering Iron Kits With Tools, Tips, And Multimeter | B7: KSh 2,999 | C7: KSh 3,290 | D7: 0.09 | E7: -15 | F7: 4 out of 5
A8: 137 Pieces Cake Decorating Tool Set Baking Supplies | B8: KSh 2,319 | C8: KSh 3,032 | D8: 0.24 | E8: -55 | F8: 4.6 out of 5
A9: Desk Foldable Fan Adjustable Fan Strong Wind 3 Gear Usb | B9: KSh 988 | C9: KSh 1,580 | D9: 0.37 | E9: -2 | F9: 4 out of 5
A10: LASA FOLDING TABLE SERVING STAND | B10: KSh 1,274 | C10: KSh 2,800 | D10: 0.55 | E10: -5 | F10: 4.8 out of 5
A11: 13 In 1 Home Repair Tools Box Kit Set | B11: KSh 1,600 | C11: KSh 2,929 | D11: 0.45 | E11: -5 | F11: 3.8 out of 5
A12: Genebre 115 In 1 Screwdriver Repairing Tool Set For IPhone Cellphone Hand Tool | B12: KSh 799 | C12: KSh 999 | D12: 0.2 | E12: -12 | F12: 4.1 out of 5
A13: 100 Pcs Crochet Hook Tool Set Knitting Hook Set With Box | B13: KSh 990 | C13: KSh 1,500 | D13: 0.34 | E13: -39 | F13: 4.7 out of 5
... A22: 3PCS Single Head Knitting Crochet Sweater Needle Set | B22: KSh 38 | C22: KSh 80 | D22: 0.53 | E22: -13 | F22: 3.3 out of 5
A23: 4pcs Bathroom/Kitchen Towel Rack,Roll Paper Holder,Towel Bars,Hook | B23: KSh 1,860 | C23: KSh 3,220 | D23: 0.42
A24: LED Romantic Spaceship Starry Sky Projector,Children's Bedroom Night Light-Blue | B24: KSh 880 | C24: KSh 1,350 | D24: 0.35 | E24: -6 | F24: 4 out of 5
A25: Foldable Overbed Table/Desk | B25: KSh 1,650 | C25: KSh 2,150 | D25: 0.23 | E25: -14 | F25: 4.4 out of 5
A26: LASA 3 Tier Bamboo Shoe Bench Storage Shelf | B26: KSh 2,048 | C26: KSh 4,500 | D26: 0.54 | E26: -7 | F26: 4.3 out of 5
A27: Electronic Digital Display Vernier Caliper | B27: KSh 420 | C27: KSh 647 | D27: 0.35 | E27: -49 | F27: 4.6 out of 5
A28: Portable Wardrobe Nonwoven With 3 Hanging Rods And 6 Storage Shelves | B28: KSh 2,880 | C28: KSh 3,520 | D28: 0.18 | E28: -12 | F28: 3.8 out of 5
A29: 12 Litre Black Insulated Lunch Box | B29: KSh 1,350 | C29: KSh 1,990 | D29: 0.32 | E29: -13 | F29: 3.8 out of 5
A30: 52 Pieces Cake Decorating Tool Set Gift Kit Baking Supplies | B30: KSh 1,758 | C30: KSh 2,499 | D30: 0.3 | E30: -20 | F30: 4.1 out of 5
A31: MultiFunctional Storage Rack Multi-layer Bookshelf | B31: KSh 2,200 | C31: KSh 4,080 | D31: 0.46
A32: Exfoliate And Exfoliate Face Towel - Black | B32: KSh 185 | C32: KSh 382 | D32: 0.52 | E32: -9 | F32: 4.3 out of 5
A33: 12 Litre Insulated Lunch Box Grey | B33: KSh 980 | C33: KSh 1,490 | D33: 0.34 | E33: -12 | F33: 4.7 out of 5
A34: LED Eye Protection Desk Lamp , Study, Reading, USB Fan - Double Pen Holder | B34: KSh 1,820 | C34: KSh 3,490 | D34: 0.48 | E34: -9 | F34: 4.3 out of 5
A35: 53Pcs/Set Yarn Knitting Crochet Hooks With Bag - Fortune Cat | B35: KSh 1,940 | C35: KSh 2,650 | D35: 0.27 | E35: -20 | F35: 4.7 out of 5
A36: 53 Pieces/Set Yarn Knitting Crochet Hooks With Bag - Pansies | B36: KSh 1,980 | C36: KSh 2,699 | D36: 0.27 | E36: -32 | F36: 4.5 out of 5
A37: DIY File Folder, Office Drawer File Holder, Pen Holder, Desktop Storage Rack | B37: KSh 1,620 | C37: KSh 2,690 | D37: 0.4 | E37: -1 | F37: 5 out of 5
A38: Classic Black Cat Cotton Hemp Pillow Case For Home Car | B38: KSh 171 | C38: KSh 360 | D38: 0.53 | E38: -2 | F38: 5 out of 5
A39: Punch-free Great Load Bearing Bathroom Storage Rack Wall Shelf-White | B39: KSh 389 | C39: KSh 656 | D39: 0.41 | E39: -36 | F39: 4.3 out of 5
A40: 1/2/3 Seater Elastic Sofa Cover,Living Room/Home Decor Chair Cover-Grey | B40: KSh 1,620 - KSh 1,980 | C40: KSh 2,200 - KSh 3,200 | D40: 0.38 | E40: -2 | F40: 4.5 out of 5
A41: LASA Stainless Steel Double Wall Mount Soap Dispenser - 500ml | B41: KSh 2,750 | C41: KSh 4,471 | D41: 0.38
A42: 4M Float Switch Water Level Controller -Water Tank | B42: KSh 475 | C42: KSh 931 | D42: 0.49
A43: Modern Sofa Throw Pillow Cover-45x45cm-Blue&Red | B43: KSh 238 | C43: KSh 476 | D43: 0.5
A44: Balloon Insert, Birthday Party Balloon Set, PU Leather | B44: KSh 610 | C44: KSh 1,060 | D44: 0.42
A45: Balloon Insert, Birthday Party Balloon Set, PU Leather | B45: KSh 610 | C45: KSh 1,060 | D45: 0.42
A46: Shower Cap Wide Elastic Band Cover Reusable Bashroom Cap | B46: KSh 2,132 | C46: KSh 2,169 | D46: 0.02
A47: Christmas Elk Fence Yard Lawn Decorations Cute For Holidays | B47: KSh 999 | C47: KSh 2,000 | D47: 0.5
A48: 60W Hot Melt Glue Sprayer - Efficient And Stable Glue Dispensing | B48: KSh 1,190 | C48: KSh 1,785 | D48: 0.33
...

Sheet Cleaned_Dataset
A1: Product | B1: Current price (Ksh) | C1: old price (Ksh) | D1: Discount | E1: Review | F1: Rating | G1: Rating Category | H1: Discount Category | I1: Discount Amount | J1: Rating Rank Key | K1: Review Rank Key | L1: Discount Rank Key
A2: 115 Piece Set Of Multifunctional Precision Screwdrivers | B2: 950 | C2: 1525 | D2: 0.38 | E2: 2 | F2: 4.5 | G2: =IF(tblProducts[[#This Row],[Rating]]="","Missing",IF(tblProducts[[#This Row],[Rating]]<3,"Poor",IF(tblProducts[[#This Row],[Rating]]<=4.5,"Average","Excellent"))) -> Average | H2: =IF(tblProducts[[#This Row],[Discount]]="","Missing",IF(tblProducts[[#This Row],[Discount]]<20%,"Low Discount",IF(tblProducts[[#This Row],[Discount]]<=40%,"Medium Discount","High Discount"))) -> Medium Discount | I2: =tblProducts[[#This Row],[old price (Ksh)]]-tblProducts[[#This Row],[Current price (Ksh)]] -> 575 | J2: =IF(tblProducts[[#This Row],[Rating]]="","",tblProducts[[#This Row],[Rating]]+tblProducts[[#This Row],[Review]]/1000000+ROW()/100000000) -> 4.500002 | K2: =IF(tblProducts[[#This Row],[Review]]="","",tblProducts[[#This Row],[Review]]+tblProducts[[#This Row],[Rating]]/1000) -> 2.0045 | L2: =IF(tblProducts[[#This Row],[Discount]]="","",tblProducts[[#This Row],[Discount]]+tblProducts[[#This Row],[Review]]/1000000) -> 0.380002
A3: Metal Decorative Hooks Key Hangers Entryway Wall Hooks Towel Hooks - Home | B3: 527 | C3: 999 | D3: 0.47 | E3: 14 | F3: 4.1 | G3: =IF(tblProducts[[#This Row],[Rating]]="","Missing",IF(tblProducts[[#This Row],[Rating]]<3,"Poor",IF(tblProducts[[#This Row],[Rating]]<=4.5,"Average","Excellent"))) -> Average | H3: =IF(tblProducts[[#This Row],[Discount]]="","Missing",IF(tblProducts[[#This Row],[Discount]]<20%,"Low Discount",IF(tblProducts[[#This Row],[Discount]]<=40%,"Medium Discount","High Discount"))) -> High Discount | I3: =tblProducts[[#This Row],[old price (Ksh)]]-tblProducts[[#This Row],[Current price (Ksh)]] -> 472 | J3: =IF(tblProducts[[#This Row],[Rating]]="","",tblProducts[[#This Row],[Rating]]+tblProducts[[#This Row],[Review]]/1000000+ROW()/100000000) -> 4.100014 | K3: =IF(tblProducts[[#This Row],[Review]]="","",tblProducts[[#This Row],[Review]]+tblProducts[[#This Row],[Rating]]/1000) -> 14.0041 | L3: =IF(tblProducts[[#This Row],[Discount]]="","",tblProducts[[#This Row],[Discount]]+tblProducts[[#This Row],[Review]]/1000000) -> 0.470014
A4: Portable Mini Cordless Car Vacuum Cleaner - Blue | B4: 2199 | C4: 2923 | D4: 0.25 | E4: 24 | F4: 4.6 | G4: =IF(tblProducts[[#This Row],[Rating]]="","Missing",IF(tblProducts[[#This Row],[Rating]]<3,"Poor",IF(tblProducts[[#This Row],[Rating]]<=4.5,"Average","Excellent"))) -> Excellent | H4: =IF(tblProducts[[#This Row],[Discount]]="","Missing",IF(tblProducts[[#This Row],[Discount]]<20%,"Low Discount",IF(tblProducts[[#This Row],[Discount]]<=40%,"Medium Discount","High Discount"))) -> Medium Discount | I4: =tblProducts[[#This Row],[old price (Ksh)]]-tblProducts[[#This Row],[Current price (Ksh)]] -> 724 | J4: =IF(tblProducts[[#This Row],[Rating]]="","",tblProducts[[#This Row],[Rating]]+tblProducts[[#This Row],[Review]]/1000000+ROW()/100000000) -> 4.600024 | K4: =IF(tblProducts[[#This Row],[Review]]="","",tblProducts[[#This Row],[Review]]+tblProducts[[#This Row],[Rating]]/1000) -> 24.0046 | L4: =IF(tblProducts[[#This Row],[Discount]]="","",tblProducts[[#This Row],[Discount]]+tblProducts[[#This Row],[Review]]/1000000) -> 0.250024
A5: Weighing Scale Digital Bathroom Body Fat Scale USB-Black | B5: 1580 | C5: 2499 | D5: 0.37 | E5: 7 | F5: 4.7 | G5: =IF(tblProducts[[#This Row],[Rating]]="","Missing",IF(tblProducts[[#This Row],[Rating]]<3,"Poor",IF(tblProducts[[#This Row],[Rating]]<=4.5,"Average","Excellent"))) -> Excellent | H5: =IF(tblProducts[[#This Row],[Discount]]="","Missing",IF(tblProducts[[#This Row],[Discount]]<20%,"Low Discount",IF(tblProducts[[#This Row],[Discount]]<=40%,"Medium Discount","High Discount"))) -> Medium Discount | I5: =tblProducts[[#This Row],[old price (Ksh)]]-tblProducts[[#This Row],[Current price (Ksh)]] -> 919 | J5: =IF(tblProducts[[#This Row],[Rating]]="","",tblProducts[[#This Row],[Rating]]+tblProducts[[#This Row],[Review]]/1000000+ROW()/100000000) -> 4.700007 | K5: =IF(tblProducts[[#This Row],[Review]]="","",tblProducts[[#This Row],[Review]]+tblProducts[[#This Row],[Rating]]/1000) -> 7.0047 | L5: =IF(tblProducts[[#This Row],[Discount]]="","",tblProducts[[#This Row],[Discount]]+tblProducts[[#This Row],[Review]]/1000000) -> 0.370007
A6: Portable Home Small Air Humidifier 3-Speed Fan - Green | B6: 1740 | C6: 2356 | D6: 0.26 | E6: 5 | F6: 4.8 | G6: =IF(tblProducts[[#This Row],[Rating]]="","Missing",IF(tblProducts[[#This Row],[Rating]]<3,"Poor",IF(tblProducts[[#This Row],[Rating]]<=4.5,"Average","Excellent"))) -> Excellent | H6: =IF(tblProducts[[#This Row],[Discount]]="","Missing",IF(tblProducts[[#This Row],[Discount]]<20%,"Low Discount",IF(tblProducts[[#This Row],[Discount]]<=40%,"Medium Discount","High Discount"))) -> Medium Discount | I6: =tblProducts[[#This Row],[old price (Ksh)]]-tblProducts[[#This Row],[Current price (Ksh)]] -> 616 | J6: =IF(tblProducts[[#This Row],[Rating]]="","",tblProducts[[#This Row],[Rating]]+tblProducts[[#This Row],[Review]]/1000000+ROW()/100000000) -> 4.8000051 | K6: =IF(tblProducts[[#This Row],[Review]]="","",tblProducts[[#This Row],[Review]]+tblProducts[[#This Row],[Rating]]/1000) -> 5.0048 | L6: =IF(tblProducts[[#This Row],[Discount]]="","",tblProducts[[#This Row],[Discount]]+tblProducts[[#This Row],[Review]]/1000000) -> 0.260005
A7: 220V 60W Electric Soldering Iron Kits With Tools, Tips, And Multimeter | B7: 2999 | C7: 3290 | D7: 0.09 | E7: 15 | F7: 4 | G7: =IF(tblProducts[[#This Row],[Rating]]="","Missing",IF(tblProducts[[#This Row],[Rating]]<3,"Poor",IF(tblProducts[[#This Row],[Rating]]<=4.5,"Average","Excellent"))) -> Average | H7: =IF(tblProducts[[#This Row],[Discount]]="","Missing",IF(tblProducts[[#This Row],[Discount]]<20%,"Low Discount",IF(tblProducts[[#This Row],[Discount]]<=40%,"Medium Discount","High Discount"))) -> Low Discount | I7: =tblProducts[[#This Row],[old price (Ksh)]]-tblProducts[[#This Row],[Current price (Ksh)]] -> 291 | J7: =IF(tblProducts[[#This Row],[Rating]]="","",tblProducts[[#This Row],[Rating]]+tblProducts[[#This Row],[Review]]/1000000+ROW()/100000000) -> 4.0000151 | K7: =IF(tblProducts[[#This Row],[Review]]="","",tblProducts[[#This Row],[Review]]+tblProducts[[#This Row],[Rating]]/1000) -> 15.004 | L7: =IF(tblProducts[[#This Row],[Discount]]="","",tblProducts[[#This Row],[Discount]]+tblProducts[[#This Row],[Review]]/1000000) -> 0.090015
A8: 137 Pieces Cake Decorating Tool Set Baking Supplies | B8: 2319 | C8: 3032 | D8: 0.24 | E8: 55 | F8: 4.6 | G8: =IF(tblProducts[[#This Row],[Rating]]="","Missing",IF(tblProducts[[#This Row],[Rating]]<3,"Poor",IF(tblProducts[[#This Row],[Rating]]<=4.5,"Average","Excellent"))) -> Excellent | H8: =IF(tblProducts[[#This Row],[Discount]]="","Missing",IF(tblProducts[[#This Row],[Discount]]<20%,"Low Discount",IF(tblProducts[[#This Row],[Discount]]<=40%,"Medium Discount","High Discount"))) -> Medium Discount | I8: =tblProducts[[#This Row],[old price (Ksh)]]-tblProducts[[#This Row],[Current price (Ksh)]] -> 713 | J8: =IF(tblProducts[[#This Row],[Rating]]="","",tblProducts[[#This Row],[Rating]]+tblProducts[[#This Row],[Review]]/1000000+ROW()/100000000) -> 4.6000551 | K8: =IF(tblProducts[[#This Row],[Review]]="","",tblProducts[[#This Row],[Review]]+tblProducts[[#This Row],[Rating]]/1000) -> 55.0046 | L8: =IF(tblProducts[[#This Row],[Discount]]="","",tblProducts[[#This Row],[Discount]]+tblProducts[[#This Row],[Review]]/1000000) -> 0.240055
A9: Desk Foldable Fan Adjustable Fan Strong Wind 3 Gear USB | B9: 988 | C9: 1580 | D9: 0.37 | E9: 2 | F9: 4 | G9: =IF(tblProducts[[#This Row],[Rating]]="","Missing",IF(tblProducts[[#This Row],[Rating]]<3,"Poor",IF(tblProducts[[#This Row],[Rating]]<=4.5,"Average","Excellent"))) -> Average | H9: =IF(tblProducts[[#This Row],[Discount]]="","Missing",IF(tblProducts[[#This Row],[Discount]]<20%,"Low Discount",IF(tblProducts[[#This Row],[Discount]]<=40%,"Medium Discount","High Discount"))) -> Medium Discount | I9: =tblProducts[[#This Row],[old price (Ksh)]]-tblProducts[[#This Row],[Current price (Ksh)]] -> 592 | J9: =IF(tblProducts[[#This Row],[Rating]]="","",tblProducts[[#This Row],[Rating]]+tblProducts[[#This Row],[Review]]/1000000+ROW()/100000000) -> 4.0000021 | K9: =IF(tblProducts[[#This Row],[Review]]="","",tblProducts[[#This Row],[Review]]+tblProducts[[#This Row],[Rating]]/1000) -> 2.004 | L9: =IF(tblProducts[[#This Row],[Discount]]="","",tblProducts[[#This Row],[Discount]]+tblProducts[[#This Row],[Review]]/1000000) -> 0.370002
A10: Lasa Folding Table Serving Stand | B10: 1274 | C10: 2800 | D10: 0.55 | E10: 5 | F10: 4.8 | G10: =IF(tblProducts[[#This Row],[Rating]]="","Missing",IF(tblProducts[[#This Row],[Rating]]<3,"Poor",IF(tblProducts[[#This Row],[Rating]]<=4.5,"Average","Excellent"))) -> Excellent | H10: =IF(tblProducts[[#This Row],[Discount]]="","Missing",IF(tblProducts[[#This Row],[Discount]]<20%,"Low Discount",IF(tblProducts[[#This Row],[Discount]]<=40%,"Medium Discount","High Discount"))) -> High Discount | I10: =tblProducts[[#This Row],[old price (Ksh)]]-tblProducts[[#This Row],[Current price (Ksh)]] -> 1526 | J10: =IF(tblProducts[[#This Row],[Rating]]="","",tblProducts[[#This Row],[Rating]]+tblProducts[[#This Row],[Review]]/1000000+ROW()/100000000) -> 4.8000051 | K10: =IF(tblProducts[[#This Row],[Review]]="","",tblProducts[[#This Row],[Review]]+tblProducts[[#This Row],[Rating]]/1000) -> 5.0048 | L10: =IF(tblProducts[[#This Row],[Discount]]="","",tblProducts[[#This Row],[Discount]]+tblProducts[[#This Row],[Review]]/1000000) -> 0.550005
A11: 13 In 1 Home Repair Tools Box Kit Set | B11: 1600 | C11: 2929 | D11: 0.45 | E11: 5 | F11: 3.8 | G11: =IF(tblProducts[[#This Row],[Rating]]="","Missing",IF(tblProducts[[#This Row],[Rating]]<3,"Poor",IF(tblProducts[[#This Row],[Rating]]<=4.5,"Average","Excellent"))) -> Average | H11: =IF(tblProducts[[#This Row],[Discount]]="","Missing",IF(tblProducts[[#This Row],[Discount]]<20%,"Low Discount",IF(tblProducts[[#This Row],[Discount]]<=40%,"Medium Discount","High Discount"))) -> High Discount | I11: =tblProducts[[#This Row],[old price (Ksh)]]-tblProducts[[#This Row],[Current price (Ksh)]] -> 1329 | J11: =IF(tblProducts[[#This Row],[Rating]]="","",tblProducts[[#This Row],[Rating]]+tblProducts[[#This Row],[Review]]/1000000+ROW()/100000000) -> 3.8000051 | K11: =IF(tblProducts[[#This Row],[Review]]="","",tblProducts[[#This Row],[Review]]+tblProducts[[#This Row],[Rating]]/1000) -> 5.0038 | L11: =IF(tblProducts[[#This Row],[Discount]]="","",tblProducts[[#This Row],[Discount]]+tblProducts[[#This Row],[Review]]/1000000) -> 0.450005
A12: Genebre 115 In 1 Screwdriver Repairing Tool Set For iPhone Cellphone Hand Tool | B12: 799 | C12: 999 | D12: 0.2 | E12: 12 | F12: 4.1 | G12: =IF(tblProducts[[#This Row],[Rating]]="","Missing",IF(tblProducts[[#This Row],[Rating]]<3,"Poor",IF(tblProducts[[#This Row],[Rating]]<=4.5,"Average","Excellent"))) -> Average | H12: =IF(tblProducts[[#This Row],[Discount]]="","Missing",IF(tblProducts[[#This Row],[Discount]]<20%,"Low Discount",IF(tblProducts[[#This Row],[Discount]]<=40%,"Medium Discount","High Discount"))) -> Medium Discount | I12: =tblProducts[[#This Row],[old price (Ksh)]]-tblProducts[[#This Row],[Current price (Ksh)]] -> 200 | J12: =IF(tblProducts[[#This Row],[Rating]]="","",tblProducts[[#This Row],[Rating]]+tblProducts[[#This Row],[Review]]/1000000+ROW()/100000000) -> 4.1000121 | K12: =IF(tblProducts[[#This Row],[Review]]="","",tblProducts[[#This Row],[Review]]+tblProducts[[#This Row],[Rating]]/1000) -> 12.0041 | L12: =IF(tblProducts[[#This Row],[Discount]]="","",tblProducts[[#This Row],[Discount]]+tblProducts[[#This Row],[Review]]/1000000) -> 0.200012
A13: 100 Pcs Crochet Hook Tool Set Knitting Hook Set With Box | B13: 990 | C13: 1500 | D13: 0.34 | E13: 39 | F13: 4.7 | G13: =IF(tblProducts[[#This Row],[Rating]]="","Missing",IF(tblProducts[[#This Row],[Rating]]<3,"Poor",IF(tblProducts[[#This Row],[Rating]]<=4.5,"Average","Excellent"))) -> Excellent | H13: =IF(tblProducts[[#This Row],[Discount]]="","Missing",IF(tblProducts[[#This Row],[Discount]]<20%,"Low Discount",IF(tblProducts[[#This Row],[Discount]]<=40%,"Medium Discount","High Discount"))) -> Medium Discount | I13: =tblProducts[[#This Row],[old price (Ksh)]]-tblProducts[[#This Row],[Current price (Ksh)]] -> 510 | J13: =IF(tblProducts[[#This Row],[Rating]]="","",tblProducts[[#This Row],[Rating]]+tblProducts[[#This Row],[Review]]/1000000+ROW()/100000000) -> 4.7000391 | K13: =IF(tblProducts[[#This Row],[Review]]="","",tblProducts[[#This Row],[Review]]+tblProducts[[#This Row],[Rating]]/1000) -> 39.0047 | L13: =IF(tblProducts[[#This Row],[Discount]]="","",tblProducts[[#This Row],[Discount]]+tblProducts[[#This Row],[Review]]/1000000) -> 0.340039
... A22: 3Pcs Single Head Knitting Crochet Sweater Needle Set | B22: 38 | C22: 80 | D22: 0.53 | E22: 13 | F22: 3.3 | G22: =IF(tblProducts[[#This Row],[Rating]]="","Missing",IF(tblProducts[[#This Row],[Rating]]<3,"Poor",IF(tblProducts[[#This Row],[Rating]]<=4.5,"Average","Excellent"))) -> Average | H22: =IF(tblProducts[[#This Row],[Discount]]="","Missing",IF(tblProducts[[#This Row],[Discount]]<20%,"Low Discount",IF(tblProducts[[#This Row],[Discount]]<=40%,"Medium Discount","High Discount"))) -> High Discount | I22: =tblProducts[[#This Row],[old price (Ksh)]]-tblProducts[[#This Row],[Current price (Ksh)]] -> 42 | J22: =IF(tblProducts[[#This Row],[Rating]]="","",tblProducts[[#This Row],[Rating]]+tblProducts[[#This Row],[Review]]/1000000+ROW()/100000000) -> 3.3000132 | K22: =IF(tblProducts[[#This Row],[Review]]="","",tblProducts[[#This Row],[Review]]+tblProducts[[#This Row],[Rating]]/1000) -> 13.0033 | L22: =IF(tblProducts[[#This Row],[Discount]]="","",tblProducts[[#This Row],[Discount]]+tblProducts[[#This Row],[Review]]/1000000) -> 0.530013
A23: 4Pcs Bathroom/Kitchen Towel Rack,Roll Paper Holder,Towel Bars,Hook | B23: 1860 | C23: 3220 | D23: 0.42 | G23: =IF(tblProducts[[#This Row],[Rating]]="","Missing",IF(tblProducts[[#This Row],[Rating]]<3,"Poor",IF(tblProducts[[#This Row],[Rating]]<=4.5,"Average","Excellent"))) -> Missing | H23: =IF(tblProducts[[#This Row],[Discount]]="","Missing",IF(tblProducts[[#This Row],[Discount]]<20%,"Low Discount",IF(tblProducts[[#This Row],[Discount]]<=40%,"Medium Discount","High Discount"))) -> High Discount | I23: =tblProducts[[#This Row],[old price (Ksh)]]-tblProducts[[#This Row],[Current price (Ksh)]] -> 1360 | J23: =IF(tblProducts[[#This Row],[Rating]]="","",tblProducts[[#This Row],[Rating]]+tblProducts[[#This Row],[Review]]/1000000+ROW()/100000000) | K23: =IF(tblProducts[[#This Row],[Review]]="","",tblProducts[[#This Row],[Review]]+tblProducts[[#This Row],[Rating]]/1000) | L23: =IF(tblProducts[[#This Row],[Discount]]="","",tblProducts[[#This Row],[Discount]]+tblProducts[[#This Row],[Review]]/1000000) -> 0.42
A24: LED Romantic Spaceship Starry Sky Projector,Children's Bedroom Night Light-Blue | B24: 880 | C24: 1350 | D24: 0.35 | E24: 6 | F24: 4 | G24: =IF(tblProducts[[#This Row],[Rating]]="","Missing",IF(tblProducts[[#This Row],[Rating]]<3,"Poor",IF(tblProducts[[#This Row],[Rating]]<=4.5,"Average","Excellent"))) -> Average | H24: =IF(tblProducts[[#This Row],[Discount]]="","Missing",IF(tblProducts[[#This Row],[Discount]]<20%,"Low Discount",IF(tblProducts[[#This Row],[Discount]]<=40%,"Medium Discount","High Discount"))) -> Medium Discount | I24: =tblProducts[[#This Row],[old price (Ksh)]]-tblProducts[[#This Row],[Current price (Ksh)]] -> 470 | J24: =IF(tblProducts[[#This Row],[Rating]]="","",tblProducts[[#This Row],[Rating]]+tblProducts[[#This Row],[Review]]/1000000+ROW()/100000000) -> 4.0000062 | K24: =IF(tblProducts[[#This Row],[Review]]="","",tblProducts[[#This Row],[Review]]+tblProducts[[#This Row],[Rating]]/1000) -> 6.004 | L24: =IF(tblProducts[[#This Row],[Discount]]="","",tblProducts[[#This Row],[Discount]]+tblProducts[[#This Row],[Review]]/1000000) -> 0.350006
A25: Foldable Overbed Table/Desk | B25: 1650 | C25: 2150 | D25: 0.23 | E25: 14 | F25: 4.4 | G25: =IF(tblProducts[[#This Row],[Rating]]="","Missing",IF(tblProducts[[#This Row],[Rating]]<3,"Poor",IF(tblProducts[[#This Row],[Rating]]<=4.5,"Average","Excellent"))) -> Average | H25: =IF(tblProducts[[#This Row],[Discount]]="","Missing",IF(tblProducts[[#This Row],[Discount]]<20%,"Low Discount",IF(tblProducts[[#This Row],[Discount]]<=40%,"Medium Discount","High Discount"))) -> Medium Discount | I25: =tblProducts[[#This Row],[old price (Ksh)]]-tblProducts[[#This Row],[Current price (Ksh)]] -> 500 | J25: =IF(tblProducts[[#This Row],[Rating]]="","",tblProducts[[#This Row],[Rating]]+tblProducts[[#This Row],[Review]]/1000000+ROW()/100000000) -> 4.4000143 | K25: =IF(tblProducts[[#This Row],[Review]]="","",tblProducts[[#This Row],[Review]]+tblProducts[[#This Row],[Rating]]/1000) -> 14.0044 | L25: =IF(tblProducts[[#This Row],[Discount]]="","",tblProducts[[#This Row],[Discount]]+tblProducts[[#This Row],[Review]]/1000000) -> 0.230014
A26: Lasa 3 Tier Bamboo Shoe Bench Storage Shelf | B26: 2048 | C26: 4500 | D26: 0.54 | E26: 7 | F26: 4.3 | G26: =IF(tblProducts[[#This Row],[Rating]]="","Missing",IF(tblProducts[[#This Row],[Rating]]<3,"Poor",IF(tblProducts[[#This Row],[Rating]]<=4.5,"Average","Excellent"))) -> Average | H26: =IF(tblProducts[[#This Row],[Discount]]="","Missing",IF(tblProducts[[#This Row],[Discount]]<20%,"Low Discount",IF(tblProducts[[#This Row],[Discount]]<=40%,"Medium Discount","High Discount"))) -> High Discount | I26: =tblProducts[[#This Row],[old price (Ksh)]]-tblProducts[[#This Row],[Current price (Ksh)]] -> 2452 | J26: =IF(tblProducts[[#This Row],[Rating]]="","",tblProducts[[#This Row],[Rating]]+tblProducts[[#This Row],[Review]]/1000000+ROW()/100000000) -> 4.3000073 | K26: =IF(tblProducts[[#This Row],[Review]]="","",tblProducts[[#This Row],[Review]]+tblProducts[[#This Row],[Rating]]/1000) -> 7.0043 | L26: =IF(tblProducts[[#This Row],[Discount]]="","",tblProducts[[#This Row],[Discount]]+tblProducts[[#This Row],[Review]]/1000000) -> 0.540007
A27: Electronic Digital Display Vernier Caliper | B27: 420 | C27: 647 | D27: 0.35 | E27: 49 | F27: 4.6 | G27: =IF(tblProducts[[#This Row],[Rating]]="","Missing",IF(tblProducts[[#This Row],[Rating]]<3,"Poor",IF(tblProducts[[#This Row],[Rating]]<=4.5,"Average","Excellent"))) -> Excellent | H27: =IF(tblProducts[[#This Row],[Discount]]="","Missing",IF(tblProducts[[#This Row],[Discount]]<20%,"Low Discount",IF(tblProducts[[#This Row],[Discount]]<=40%,"Medium Discount","High Discount"))) -> Medium Discount | I27: =tblProducts[[#This Row],[old price (Ksh)]]-tblProducts[[#This Row],[Current price (Ksh)]] -> 227 | J27: =IF(tblProducts[[#This Row],[Rating]]="","",tblProducts[[#This Row],[Rating]]+tblProducts[[#This Row],[Review]]/1000000+ROW()/100000000) -> 4.6000493 | K27: =IF(tblProducts[[#This Row],[Review]]="","",tblProducts[[#This Row],[Review]]+tblProducts[[#This Row],[Rating]]/1000) -> 49.0046 | L27: =IF(tblProducts[[#This Row],[Discount]]="","",tblProducts[[#This Row],[Discount]]+tblProducts[[#This Row],[Review]]/1000000) -> 0.350049
A28: Portable Wardrobe Nonwoven With 3 Hanging Rods And 6 Storage Shelves | B28: 2880 | C28: 3520 | D28: 0.18 | E28: 12 | F28: 3.8 | G28: =IF(tblProducts[[#This Row],[Rating]]="","Missing",IF(tblProducts[[#This Row],[Rating]]<3,"Poor",IF(tblProducts[[#This Row],[Rating]]<=4.5,"Average","Excellent"))) -> Average | H28: =IF(tblProducts[[#This Row],[Discount]]="","Missing",IF(tblProducts[[#This Row],[Discount]]<20%,"Low Discount",IF(tblProducts[[#This Row],[Discount]]<=40%,"Medium Discount","High Discount"))) -> Low Discount | I28: =tblProducts[[#This Row],[old price (Ksh)]]-tblProducts[[#This Row],[Current price (Ksh)]] -> 640 | J28: =IF(tblProducts[[#This Row],[Rating]]="","",tblProducts[[#This Row],[Rating]]+tblProducts[[#This Row],[Review]]/1000000+ROW()/100000000) -> 3.8000123 | K28: =IF(tblProducts[[#This Row],[Review]]="","",tblProducts[[#This Row],[Review]]+tblProducts[[#This Row],[Rating]]/1000) -> 12.0038 | L28: =IF(tblProducts[[#This Row],[Discount]]="","",tblProducts[[#This Row],[Discount]]+tblProducts[[#This Row],[Review]]/1000000) -> 0.180012
A29: 12 Litre Black Insulated Lunch Box | B29: 1350 | C29: 1990 | D29: 0.32 | E29: 13 | F29: 3.8 | G29: =IF(tblProducts[[#This Row],[Rating]]="","Missing",IF(tblProducts[[#This Row],[Rating]]<3,"Poor",IF(tblProducts[[#This Row],[Rating]]<=4.5,"Average","Excellent"))) -> Average | H29: =IF(tblProducts[[#This Row],[Discount]]="","Missing",IF(tblProducts[[#This Row],[Discount]]<20%,"Low Discount",IF(tblProducts[[#This Row],[Discount]]<=40%,"Medium Discount","High Discount"))) -> Medium Discount | I29: =tblProducts[[#This Row],[old price (Ksh)]]-tblProducts[[#This Row],[Current price (Ksh)]] -> 640 | J29: =IF(tblProducts[[#This Row],[Rating]]="","",tblProducts[[#This Row],[Rating]]+tblProducts[[#This Row],[Review]]/1000000+ROW()/100000000) -> 3.8000133 | K29: =IF(tblProducts[[#This Row],[Review]]="","",tblProducts[[#This Row],[Review]]+tblProducts[[#This Row],[Rating]]/1000) -> 13.0038 | L29: =IF(tblProducts[[#This Row],[Discount]]="","",tblProducts[[#This Row],[Discount]]+tblProducts[[#This Row],[Review]]/1000000) -> 0.320013
A30: 52 Pieces Cake Decorating Tool Set Gift Kit Baking Supplies | B30: 1758 | C30: 2499 | D30: 0.3 | E30: 20 | F30: 4.1 | G30: =IF(tblProducts[[#This Row],[Rating]]="","Missing",IF(tblProducts[[#This Row],[Rating]]<3,"Poor",IF(tblProducts[[#This Row],[Rating]]<=4.5,"Average","Excellent"))) -> Average | H30: =IF(tblProducts[[#This Row],[Discount]]="","Missing",IF(tblProducts[[#This Row],[Discount]]<20%,"Low Discount",IF(tblProducts[[#This Row],[Discount]]<=40%,"Medium Discount","High Discount"))) -> Medium Discount | I30: =tblProducts[[#This Row],[old price (Ksh)]]-tblProducts[[#This Row],[Current price (Ksh)]] -> 741 | J30: =IF(tblProducts[[#This Row],[Rating]]="","",tblProducts[[#This Row],[Rating]]+tblProducts[[#This Row],[Review]]/1000000+ROW()/100000000) -> 4.1000203 | K30: =IF(tblProducts[[#This Row],[Review]]="","",tblProducts[[#This Row],[Review]]+tblProducts[[#This Row],[Rating]]/1000) -> 20.0041 | L30: =IF(tblProducts[[#This Row],[Discount]]="","",tblProducts[[#This Row],[Discount]]+tblProducts[[#This Row],[Review]]/1000000) -> 0.30002
A31: Multifunctional Storage Rack Multi-Layer Booelf | B31: 2200 | C31: 4080 | D31: 0.46 | G31: =IF(tblProducts[[#This Row],[Rating]]="","Missing",IF(tblProducts[[#This Row],[Rating]]<3,"Poor",IF(tblProducts[[#This Row],[Rating]]<=4.5,"Average","Excellent"))) -> Missing | H31: =IF(tblProducts[[#This Row],[Discount]]="","Missing",IF(tblProducts[[#This Row],[Discount]]<20%,"Low Discount",IF(tblProducts[[#This Row],[Discount]]<=40%,"Medium Discount","High Discount"))) -> High Discount | I31: =tblProducts[[#This Row],[old price (Ksh)]]-tblProducts[[#This Row],[Current price (Ksh)]] -> 1880 | J31: =IF(tblProducts[[#This Row],[Rating]]="","",tblProducts[[#This Row],[Rating]]+tblProducts[[#This Row],[Review]]/1000000+ROW()/100000000) | K31: =IF(tblProducts[[#This Row],[Review]]="","",tblProducts[[#This Row],[Review]]+tblProducts[[#This Row],[Rating]]/1000) | L31: =IF(tblProducts[[#This Row],[Discount]]="","",tblProducts[[#This Row],[Discount]]+tblProducts[[#This Row],[Review]]/1000000) -> 0.46
A32: Exfoliate And Exfoliate Face Towel - Black | B32: 185 | C32: 382 | D32: 0.52 | E32: 9 | F32: 4.3 | G32: =IF(tblProducts[[#This Row],[Rating]]="","Missing",IF(tblProducts[[#This Row],[Rating]]<3,"Poor",IF(tblProducts[[#This Row],[Rating]]<=4.5,"Average","Excellent"))) -> Average | H32: =IF(tblProducts[[#This Row],[Discount]]="","Missing",IF(tblProducts[[#This Row],[Discount]]<20%,"Low Discount",IF(tblProducts[[#This Row],[Discount]]<=40%,"Medium Discount","High Discount"))) -> High Discount | I32: =tblProducts[[#This Row],[old price (Ksh)]]-tblProducts[[#This Row],[Current price (Ksh)]] -> 197 | J32: =IF(tblProducts[[#This Row],[Rating]]="","",tblProducts[[#This Row],[Rating]]+tblProducts[[#This Row],[Review]]/1000000+ROW()/100000000) -> 4.3000093 | K32: =IF(tblProducts[[#This Row],[Review]]="","",tblProducts[[#This Row],[Review]]+tblProducts[[#This Row],[Rating]]/1000) -> 9.0043 | L32: =IF(tblProducts[[#This Row],[Discount]]="","",tblProducts[[#This Row],[Discount]]+tblProducts[[#This Row],[Review]]/1000000) -> 0.520009
A33: 12 Litre Insulated Lunch Box Grey | B33: 980 | C33: 1490 | D33: 0.34 | E33: 12 | F33: 4.7 | G33: =IF(tblProducts[[#This Row],[Rating]]="","Missing",IF(tblProducts[[#This Row],[Rating]]<3,"Poor",IF(tblProducts[[#This Row],[Rating]]<=4.5,"Average","Excellent"))) -> Excellent | H33: =IF(tblProducts[[#This Row],[Discount]]="","Missing",IF(tblProducts[[#This Row],[Discount]]<20%,"Low Discount",IF(tblProducts[[#This Row],[Discount]]<=40%,"Medium Discount","High Discount"))) -> Medium Discount | I33: =tblProducts[[#This Row],[old price (Ksh)]]-tblProducts[[#This Row],[Current price (Ksh)]] -> 510 | J33: =IF(tblProducts[[#This Row],[Rating]]="","",tblProducts[[#This Row],[Rating]]+tblProducts[[#This Row],[Review]]/1000000+ROW()/100000000) -> 4.7000123 | K33: =IF(tblProducts[[#This Row],[Review]]="","",tblProducts[[#This Row],[Review]]+tblProducts[[#This Row],[Rating]]/1000) -> 12.0047 | L33: =IF(tblProducts[[#This Row],[Discount]]="","",tblProducts[[#This Row],[Discount]]+tblProducts[[#This Row],[Review]]/1000000) -> 0.340012
A34: LED Eye Protection Desk Lamp , Study, Reading, USB Fan - Double Pen Holder | B34: 1820 | C34: 3490 | D34: 0.48 | E34: 9 | F34: 4.3 | G34: =IF(tblProducts[[#This Row],[Rating]]="","Missing",IF(tblProducts[[#This Row],[Rating]]<3,"Poor",IF(tblProducts[[#This Row],[Rating]]<=4.5,"Average","Excellent"))) -> Average | H34: =IF(tblProducts[[#This Row],[Discount]]="","Missing",IF(tblProducts[[#This Row],[Discount]]<20%,"Low Discount",IF(tblProducts[[#This Row],[Discount]]<=40%,"Medium Discount","High Discount"))) -> High Discount | I34: =tblProducts[[#This Row],[old price (Ksh)]]-tblProducts[[#This Row],[Current price (Ksh)]] -> 1670 | J34: =IF(tblProducts[[#This Row],[Rating]]="","",tblProducts[[#This Row],[Rating]]+tblProducts[[#This Row],[Review]]/1000000+ROW()/100000000) -> 4.3000093 | K34: =IF(tblProducts[[#This Row],[Review]]="","",tblProducts[[#This Row],[Review]]+tblProducts[[#This Row],[Rating]]/1000) -> 9.0043 | L34: =IF(tblProducts[[#This Row],[Discount]]="","",tblProducts[[#This Row],[Discount]]+tblProducts[[#This Row],[Review]]/1000000) -> 0.480009
A35: 53Pcs/Set Yarn Knitting Crochet Hooks With Bag - Fortune Cat | B35: 1940 | C35: 2650 | D35: 0.27 | E35: 20 | F35: 4.7 | G35: =IF(tblProducts[[#This Row],[Rating]]="","Missing",IF(tblProducts[[#This Row],[Rating]]<3,"Poor",IF(tblProducts[[#This Row],[Rating]]<=4.5,"Average","Excellent"))) -> Excellent | H35: =IF(tblProducts[[#This Row],[Discount]]="","Missing",IF(tblProducts[[#This Row],[Discount]]<20%,"Low Discount",IF(tblProducts[[#This Row],[Discount]]<=40%,"Medium Discount","High Discount"))) -> Medium Discount | I35: =tblProducts[[#This Row],[old price (Ksh)]]-tblProducts[[#This Row],[Current price (Ksh)]] -> 710 | J35: =IF(tblProducts[[#This Row],[Rating]]="","",tblProducts[[#This Row],[Rating]]+tblProducts[[#This Row],[Review]]/1000000+ROW()/100000000) -> 4.7000203 | K35: =IF(tblProducts[[#This Row],[Review]]="","",tblProducts[[#This Row],[Review]]+tblProducts[[#This Row],[Rating]]/1000) -> 20.0047 | L35: =IF(tblProducts[[#This Row],[Discount]]="","",tblProducts[[#This Row],[Discount]]+tblProducts[[#This Row],[Review]]/1000000) -> 0.27002
A36: 53 Pieces/Set Yarn Knitting Crochet Hooks With Bag - Pansies | B36: 1980 | C36: 2699 | D36: 0.27 | E36: 32 | F36: 4.5 | G36: =IF(tblProducts[[#This Row],[Rating]]="","Missing",IF(tblProducts[[#This Row],[Rating]]<3,"Poor",IF(tblProducts[[#This Row],[Rating]]<=4.5,"Average","Excellent"))) -> Average | H36: =IF(tblProducts[[#This Row],[Discount]]="","Missing",IF(tblProducts[[#This Row],[Discount]]<20%,"Low Discount",IF(tblProducts[[#This Row],[Discount]]<=40%,"Medium Discount","High Discount"))) -> Medium Discount | I36: =tblProducts[[#This Row],[old price (Ksh)]]-tblProducts[[#This Row],[Current price (Ksh)]] -> 719 | J36: =IF(tblProducts[[#This Row],[Rating]]="","",tblProducts[[#This Row],[Rating]]+tblProducts[[#This Row],[Review]]/1000000+ROW()/100000000) -> 4.5000324 | K36: =IF(tblProducts[[#This Row],[Review]]="","",tblProducts[[#This Row],[Review]]+tblProducts[[#This Row],[Rating]]/1000) -> 32.0045 | L36: =IF(tblProducts[[#This Row],[Discount]]="","",tblProducts[[#This Row],[Discount]]+tblProducts[[#This Row],[Review]]/1000000) -> 0.270032
A37: DIY File Folder, Office Drawer File Holder, Pen Holder, Desktop Storage Rack | B37: 1620 | C37: 2690 | D37: 0.4 | E37: 1 | F37: 5 | G37: =IF(tblProducts[[#This Row],[Rating]]="","Missing",IF(tblProducts[[#This Row],[Rating]]<3,"Poor",IF(tblProducts[[#This Row],[Rating]]<=4.5,"Average","Excellent"))) -> Excellent | H37: =IF(tblProducts[[#This Row],[Discount]]="","Missing",IF(tblProducts[[#This Row],[Discount]]<20%,"Low Discount",IF(tblProducts[[#This Row],[Discount]]<=40%,"Medium Discount","High Discount"))) -> Medium Discount | I37: =tblProducts[[#This Row],[old price (Ksh)]]-tblProducts[[#This Row],[Current price (Ksh)]] -> 1070 | J37: =IF(tblProducts[[#This Row],[Rating]]="","",tblProducts[[#This Row],[Rating]]+tblProducts[[#This Row],[Review]]/1000000+ROW()/100000000) -> 5.0000014 | K37: =IF(tblProducts[[#This Row],[Review]]="","",tblProducts[[#This Row],[Review]]+tblProducts[[#This Row],[Rating]]/1000) -> 1.005 | L37: =IF(tblProducts[[#This Row],[Discount]]="","",tblProducts[[#This Row],[Discount]]+tblProducts[[#This Row],[Review]]/1000000) -> 0.400001
A38: Classic Black Cat Cotton Hemp Pillow Case For Home Car | B38: 171 | C38: 360 | D38: 0.53 | E38: 2 | F38: 5 | G38: =IF(tblProducts[[#This Row],[Rating]]="","Missing",IF(tblProducts[[#This Row],[Rating]]<3,"Poor",IF(tblProducts[[#This Row],[Rating]]<=4.5,"Average","Excellent"))) -> Excellent | H38: =IF(tblProducts[[#This Row],[Discount]]="","Missing",IF(tblProducts[[#This Row],[Discount]]<20%,"Low Discount",IF(tblProducts[[#This Row],[Discount]]<=40%,"Medium Discount","High Discount"))) -> High Discount | I38: =tblProducts[[#This Row],[old price (Ksh)]]-tblProducts[[#This Row],[Current price (Ksh)]] -> 189 | J38: =IF(tblProducts[[#This Row],[Rating]]="","",tblProducts[[#This Row],[Rating]]+tblProducts[[#This Row],[Review]]/1000000+ROW()/100000000) -> 5.0000024 | K38: =IF(tblProducts[[#This Row],[Review]]="","",tblProducts[[#This Row],[Review]]+tblProducts[[#This Row],[Rating]]/1000) -> 2.005 | L38: =IF(tblProducts[[#This Row],[Discount]]="","",tblProducts[[#This Row],[Discount]]+tblProducts[[#This Row],[Review]]/1000000) -> 0.530002
A39: Punch-Free Great Load Bearing Bathroom Storage Rack Wall Shelf-White | B39: 389 | C39: 656 | D39: 0.41 | E39: 36 | F39: 4.3 | G39: =IF(tblProducts[[#This Row],[Rating]]="","Missing",IF(tblProducts[[#This Row],[Rating]]<3,"Poor",IF(tblProducts[[#This Row],[Rating]]<=4.5,"Average","Excellent"))) -> Average | H39: =IF(tblProducts[[#This Row],[Discount]]="","Missing",IF(tblProducts[[#This Row],[Discount]]<20%,"Low Discount",IF(tblProducts[[#This Row],[Discount]]<=40%,"Medium Discount","High Discount"))) -> High Discount | I39: =tblProducts[[#This Row],[old price (Ksh)]]-tblProducts[[#This Row],[Current price (Ksh)]] -> 267 | J39: =IF(tblProducts[[#This Row],[Rating]]="","",tblProducts[[#This Row],[Rating]]+tblProducts[[#This Row],[Review]]/1000000+ROW()/100000000) -> 4.3000364 | K39: =IF(tblProducts[[#This Row],[Review]]="","",tblProducts[[#This Row],[Review]]+tblProducts[[#This Row],[Rating]]/1000) -> 36.0043 | L39: =IF(tblProducts[[#This Row],[Discount]]="","",tblProducts[[#This Row],[Discount]]+tblProducts[[#This Row],[Review]]/1000000) -> 0.410036
A40: 1/2/3 Seater Elastic Sofa Cover,Living Room/Home Decor Chair Cover-Grey | B40: 1620 | C40: 2200 | D40: 0.38 | E40: 2 | F40: 4.5 | G40: =IF(tblProducts[[#This Row],[Rating]]="","Missing",IF(tblProducts[[#This Row],[Rating]]<3,"Poor",IF(tblProducts[[#This Row],[Rating]]<=4.5,"Average","Excellent"))) -> Average | H40: =IF(tblProducts[[#This Row],[Discount]]="","Missing",IF(tblProducts[[#This Row],[Discount]]<20%,"Low Discount",IF(tblProducts[[#This Row],[Discount]]<=40%,"Medium Discount","High Discount"))) -> Medium Discount | I40: =tblProducts[[#This Row],[old price (Ksh)]]-tblProducts[[#This Row],[Current price (Ksh)]] -> 580 | J40: =IF(tblProducts[[#This Row],[Rating]]="","",tblProducts[[#This Row],[Rating]]+tblProducts[[#This Row],[Review]]/1000000+ROW()/100000000) -> 4.5000024 | K40: =IF(tblProducts[[#This Row],[Review]]="","",tblProducts[[#This Row],[Review]]+tblProducts[[#This Row],[Rating]]/1000) -> 2.0045 | L40: =IF(tblProducts[[#This Row],[Discount]]="","",tblProducts[[#This Row],[Discount]]+tblProducts[[#This Row],[Review]]/1000000) -> 0.380002
A41: Lasa Stainless Steel Double Wall Mount Soap Dispenser - 500Ml | B41: 2750 | C41: 4471 | D41: 0.38 | G41: =IF(tblProducts[[#This Row],[Rating]]="","Missing",IF(tblProducts[[#This Row],[Rating]]<3,"Poor",IF(tblProducts[[#This Row],[Rating]]<=4.5,"Average","Excellent"))) -> Missing | H41: =IF(tblProducts[[#This Row],[Discount]]="","Missing",IF(tblProducts[[#This Row],[Discount]]<20%,"Low Discount",IF(tblProducts[[#This Row],[Discount]]<=40%,"Medium Discount","High Discount"))) -> Medium Discount | I41: =tblProducts[[#This Row],[old price (Ksh)]]-tblProducts[[#This Row],[Current price (Ksh)]] -> 1721 | J41: =IF(tblProducts[[#This Row],[Rating]]="","",tblProducts[[#This Row],[Rating]]+tblProducts[[#This Row],[Review]]/1000000+ROW()/100000000) | K41: =IF(tblProducts[[#This Row],[Review]]="","",tblProducts[[#This Row],[Review]]+tblProducts[[#This Row],[Rating]]/1000) | L41: =IF(tblProducts[[#This Row],[Discount]]="","",tblProducts[[#This Row],[Discount]]+tblProducts[[#This Row],[Review]]/1000000) -> 0.38
A42: 4M Float Switch Water Level Controller -Water Tank | B42: 475 | C42: 931 | D42: 0.49 | G42: =IF(tblProducts[[#This Row],[Rating]]="","Missing",IF(tblProducts[[#This Row],[Rating]]<3,"Poor",IF(tblProducts[[#This Row],[Rating]]<=4.5,"Average","Excellent"))) -> Missing | H42: =IF(tblProducts[[#This Row],[Discount]]="","Missing",IF(tblProducts[[#This Row],[Discount]]<20%,"Low Discount",IF(tblProducts[[#This Row],[Discount]]<=40%,"Medium Discount","High Discount"))) -> High Discount | I42: =tblProducts[[#This Row],[old price (Ksh)]]-tblProducts[[#This Row],[Current price (Ksh)]] -> 456 | J42: =IF(tblProducts[[#This Row],[Rating]]="","",tblProducts[[#This Row],[Rating]]+tblProducts[[#This Row],[Review]]/1000000+ROW()/100000000) | K42: =IF(tblProducts[[#This Row],[Review]]="","",tblProducts[[#This Row],[Review]]+tblProducts[[#This Row],[Rating]]/1000) | L42: =IF(tblProducts[[#This Row],[Discount]]="","",tblProducts[[#This Row],[Discount]]+tblProducts[[#This Row],[Review]]/1000000) -> 0.49
A43: Modern Sofa Throw Pillow Cover-45X45Cm-Blue&Red | B43: 238 | C43: 476 | D43: 0.5 | G43: =IF(tblProducts[[#This Row],[Rating]]="","Missing",IF(tblProducts[[#This Row],[Rating]]<3,"Poor",IF(tblProducts[[#This Row],[Rating]]<=4.5,"Average","Excellent"))) -> Missing | H43: =IF(tblProducts[[#This Row],[Discount]]="","Missing",IF(tblProducts[[#This Row],[Discount]]<20%,"Low Discount",IF(tblProducts[[#This Row],[Discount]]<=40%,"Medium Discount","High Discount"))) -> High Discount | I43: =tblProducts[[#This Row],[old price (Ksh)]]-tblProducts[[#This Row],[Current price (Ksh)]] -> 238 | J43: =IF(tblProducts[[#This Row],[Rating]]="","",tblProducts[[#This Row],[Rating]]+tblProducts[[#This Row],[Review]]/1000000+ROW()/100000000) | K43: =IF(tblProducts[[#This Row],[Review]]="","",tblProducts[[#This Row],[Review]]+tblProducts[[#This Row],[Rating]]/1000) | L43: =IF(tblProducts[[#This Row],[Discount]]="","",tblProducts[[#This Row],[Discount]]+tblProducts[[#This Row],[Review]]/1000000) -> 0.5
A44: Balloon Insert, Birthday Party Balloon Set, Pu Leather | B44: 610 | C44: 1060 | D44: 0.42 | G44: =IF(tblProducts[[#This Row],[Rating]]="","Missing",IF(tblProducts[[#This Row],[Rating]]<3,"Poor",IF(tblProducts[[#This Row],[Rating]]<=4.5,"Average","Excellent"))) -> Missing | H44: =IF(tblProducts[[#This Row],[Discount]]="","Missing",IF(tblProducts[[#This Row],[Discount]]<20%,"Low Discount",IF(tblProducts[[#This Row],[Discount]]<=40%,"Medium Discount","High Discount"))) -> High Discount | I44: =tblProducts[[#This Row],[old price (Ksh)]]-tblProducts[[#This Row],[Current price (Ksh)]] -> 450 | J44: =IF(tblProducts[[#This Row],[Rating]]="","",tblProducts[[#This Row],[Rating]]+tblProducts[[#This Row],[Review]]/1000000+ROW()/100000000) | K44: =IF(tblProducts[[#This Row],[Review]]="","",tblProducts[[#This Row],[Review]]+tblProducts[[#This Row],[Rating]]/1000) | L44: =IF(tblProducts[[#This Row],[Discount]]="","",tblProducts[[#This Row],[Discount]]+tblProducts[[#This Row],[Review]]/1000000) -> 0.42
A45: Balloon Insert, Birthday Party Balloon Set, Pu Leather | B45: 610 | C45: 1060 | D45: 0.42 | G45: =IF(tblProducts[[#This Row],[Rating]]="","Missing",IF(tblProducts[[#This Row],[Rating]]<3,"Poor",IF(tblProducts[[#This Row],[Rating]]<=4.5,"Average","Excellent"))) -> Missing | H45: =IF(tblProducts[[#This Row],[Discount]]="","Missing",IF(tblProducts[[#This Row],[Discount]]<20%,"Low Discount",IF(tblProducts[[#This Row],[Discount]]<=40%,"Medium Discount","High Discount"))) -> High Discount | I45: =tblProducts[[#This Row],[old price (Ksh)]]-tblProducts[[#This Row],[Current price (Ksh)]] -> 450 | J45: =IF(tblProducts[[#This Row],[Rating]]="","",tblProducts[[#This Row],[Rating]]+tblProducts[[#This Row],[Review]]/1000000+ROW()/100000000) | K45: =IF(tblProducts[[#This Row],[Review]]="","",tblProducts[[#This Row],[Review]]+tblProducts[[#This Row],[Rating]]/1000) | L45: =IF(tblProducts[[#This Row],[Discount]]="","",tblProducts[[#This Row],[Discount]]+tblProducts[[#This Row],[Review]]/1000000) -> 0.42
A46: Shower Cap Wide Elastic Band Cover Reusable Bashroom Cap | B46: 2132 | C46: 2169 | D46: 0.02 | G46: =IF(tblProducts[[#This Row],[Rating]]="","Missing",IF(tblProducts[[#This Row],[Rating]]<3,"Poor",IF(tblProducts[[#This Row],[Rating]]<=4.5,"Average","Excellent"))) -> Missing | H46: =IF(tblProducts[[#This Row],[Discount]]="","Missing",IF(tblProducts[[#This Row],[Discount]]<20%,"Low Discount",IF(tblProducts[[#This Row],[Discount]]<=40%,"Medium Discount","High Discount"))) -> Low Discount | I46: =tblProducts[[#This Row],[old price (Ksh)]]-tblProducts[[#This Row],[Current price (Ksh)]] -> 37 | J46: =IF(tblProducts[[#This Row],[Rating]]="","",tblProducts[[#This Row],[Rating]]+tblProducts[[#This Row],[Review]]/1000000+ROW()/100000000) | K46: =IF(tblProducts[[#This Row],[Review]]="","",tblProducts[[#This Row],[Review]]+tblProducts[[#This Row],[Rating]]/1000) | L46: =IF(tblProducts[[#This Row],[Discount]]="","",tblProducts[[#This Row],[Discount]]+tblProducts[[#This Row],[Review]]/1000000) -> 0.02
A47: Christmas Elk Fence Yard Lawn Decorations Cute For Holidays | B47: 999 | C47: 2000 | D47: 0.5 | G47: =IF(tblProducts[[#This Row],[Rating]]="","Missing",IF(tblProducts[[#This Row],[Rating]]<3,"Poor",IF(tblProducts[[#This Row],[Rating]]<=4.5,"Average","Excellent"))) -> Missing | H47: =IF(tblProducts[[#This Row],[Discount]]="","Missing",IF(tblProducts[[#This Row],[Discount]]<20%,"Low Discount",IF(tblProducts[[#This Row],[Discount]]<=40%,"Medium Discount","High Discount"))) -> High Discount | I47: =tblProducts[[#This Row],[old price (Ksh)]]-tblProducts[[#This Row],[Current price (Ksh)]] -> 1001 | J47: =IF(tblProducts[[#This Row],[Rating]]="","",tblProducts[[#This Row],[Rating]]+tblProducts[[#This Row],[Review]]/1000000+ROW()/100000000) | K47: =IF(tblProducts[[#This Row],[Review]]="","",tblProducts[[#This Row],[Review]]+tblProducts[[#This Row],[Rating]]/1000) | L47: =IF(tblProducts[[#This Row],[Discount]]="","",tblProducts[[#This Row],[Discount]]+tblProducts[[#This Row],[Review]]/1000000) -> 0.5
A48: 60W Hot Melt Glue Sprayer - Efficient And Stable Glue Dispensing | B48: 1190 | C48: 1785 | D48: 0.33 | G48: =IF(tblProducts[[#This Row],[Rating]]="","Missing",IF(tblProducts[[#This Row],[Rating]]<3,"Poor",IF(tblProducts[[#This Row],[Rating]]<=4.5,"Average","Excellent"))) -> Missing | H48: =IF(tblProducts[[#This Row],[Discount]]="","Missing",IF(tblProducts[[#This Row],[Discount]]<20%,"Low Discount",IF(tblProducts[[#This Row],[Discount]]<=40%,"Medium Discount","High Discount"))) -> Medium Discount | I48: =tblProducts[[#This Row],[old price (Ksh)]]-tblProducts[[#This Row],[Current price (Ksh)]] -> 595 | J48: =IF(tblProducts[[#This Row],[Rating]]="","",tblProducts[[#This Row],[Rating]]+tblProducts[[#This Row],[Review]]/1000000+ROW()/100000000) | K48: =IF(tblProducts[[#This Row],[Review]]="","",tblProducts[[#This Row],[Review]]+tblProducts[[#This Row],[Rating]]/1000) | L48: =IF(tblProducts[[#This Row],[Discount]]="","",tblProducts[[#This Row],[Discount]]+tblProducts[[#This Row],[Review]]/1000000) -> 0.33
...

Sheet Analysis
A1: Key Performance Indicators (KPIs) | B1: Value | I1: Products Needing Pricing/Marketing Attention
A2: Total Products | B2: =ROWS(tblProducts[Product]) -> 115 | I2: Product | J2: Discount | K2: Discount Category | L2: Rating | M2: Rating Category
A3: Average Price (KSh) | B3: =AVERAGE(tblProducts[Current price (Ksh)]) -> 1172.7913 | I3: {=_xlfn._xlws.FILTER(tblProducts[Product],(tblProducts[Discount Category]="High Discount")*(tblProducts[Rating Category]<>"Excellent")*(tblProducts[Rating Category]<>"Missing"))} -> Metal Decorative Hooks Key Hangers Entryway Wall Hooks Towel Hooks - Home | J3: {=_xlfn._xlws.FILTER(tblProducts[Discount],(tblProducts[Discount Category]="High Discount")*(tblProducts[Rating Category]<>"Excellent")*(tblProducts[Rating Category]<>"Missing"))} -> 0.47 | K3: {=_xlfn._xlws.FILTER(tblProducts[Discount Category],(tblProducts[Discount Category]="High Discount")*(tblProducts[Rating Category]<>"Excellent")*(tblProducts[Rating Category]<>"Missing"))} -> High Discount | L3: {=_xlfn._xlws.FILTER(tblProducts[Rating],(tblProducts[Discount Category]="High Discount")*(tblProducts[Rating Category]<>"Excellent")*(tblProducts[Rating Category]<>"Missing"))} -> 4.1 | M3: {=_xlfn._xlws.FILTER(tblProducts[Rating Category],(tblProducts[Discount Category]="High Discount")*(tblProducts[Rating Category]<>"Excellent")*(tblProducts[Rating Category]<>"Missing"))} -> Average
A4: Average Discount | B4: =AVERAGE(tblProducts[Discount]) -> 0.36956522 | I4: 13 In 1 Home Repair Tools Box Kit Set | J4: 0.45 | K4: High Discount | L4: 3.8 | M4: Average
A5: Average Rating | B5: =AVERAGE(tblProducts[Rating]) -> 3.8894737 | I5: Lasa Digital Thermometer And Hydrometer | J5: 0.42 | K5: High Discount | L5: 4.5 | M5: Average
A6: Total Reviews | B6: =SUM(tblProducts[Review]) -> 723 | I6: 3Pcs Single Head Knitting Crochet Sweater Needle Set | J6: 0.53 | K6: High Discount | L6: 3.3 | M6: Average
A7: Products Needing Pricing/Marketing Attention | B7: =COUNTIFS(tblProducts[Discount Category],"High Discount",tblProducts[Rating Category],"<>Excellent",tblProducts[Rating Category],"<>Missing") -> 22 | I7: Lasa 3 Tier Bamboo Shoe Bench Storage Shelf | J7: 0.54 | K7: High Discount | L7: 4.3 | M7: Average
I8: Exfoliate And Exfoliate Face Towel - Black | J8: 0.52 | K8: High Discount | L8: 4.3 | M8: Average
I9: LED Eye Protection Desk Lamp , Study, Reading, USB Fan - Double Pen Holder | J9: 0.48 | K9: High Discount | L9: 4.3 | M9: Average
A10: Correlations | B10: Value | I10: Punch-Free Great Load Bearing Bathroom Storage Rack Wall Shelf-White | J10: 0.41 | K10: High Discount | L10: 4.3 | M10: Average
A11: Discount vs Reviews (Q1) | B11: =CORREL(tblProducts[Discount],tblProducts[Review]) -> -0.13682272 | I11: Mythco 120Cob Solar Wall Ligt With Motion Sensor And Remote Control 3 Modes | J11: 0.54 | K11: High Discount | L11: 3 | M11: Average
A12: Rating vs Reviews (Q2) | B12: =CORREL(tblProducts[Rating],tblProducts[Review]) -> 0.057209035 | I12: 5-Pcs Stainless Steel Cooking Pot Set With Steamed Slices | J12: 0.55 | K12: High Discount | L12: 2.1 | M12: Poor
A13: Price vs Rating (Q3) | B13: =CORREL(tblProducts[Current price (Ksh)],tblProducts[Rating]) -> 0.1079768 | I13: 120W Cordless Vacuum Cleaners Handheld Electric Vacuum Cleaner | J13: 0.49 | K13: High Discount | L13: 2.8 | M13: Poor
I14: Intelligent LED Body Sensor Wireless Lighting Night Light USB | J14: 0.52 | K14: High Discount | L14: 2.7 | M14: Poor
A15: Top 10 By Rating | I15: Artificial Potted Flowers Room Decorative Flowers (2 Pieces) | J15: 0.45 | K15: High Discount | L15: 2.2 | M15: Poor
A16: Rank | B16: Product | C16: Rating | D16: Real Rating | I16: 380Ml USB Rechargeable Portable Small Blenders And Juicers | J16: 0.5 | K16: High Discount | L16: 2.3 | M16: Poor
A17: 1 | B17: =INDEX(tblProducts[Product],MATCH(C17,tblProducts[Rating Rank Key],0)) -> Lasa Aluminum Folding Truck Hand Cart - 68Kg Max | C17: =LARGE(tblProducts[Rating Rank Key],A17) -> 5.0000032 | D17: =INDEX(tblProducts[Rating],MATCH(C17,tblProducts[Rating Rank Key],0)) -> 5 | I17: Agapeon Toothbrush Holder And Toothpaste Dispenser | J17: 0.45 | K17: High Discount | L17: 2.6 | M17: Poor
A18: 2 | B18: =INDEX(tblProducts[Product],MATCH(C18,tblProducts[Rating Rank Key],0)) -> Classic Black Cat Cotton Hemp Pillow Case For Home Car | C18: =LARGE(tblProducts[Rating Rank Key],A18) -> 5.0000024 | D18: =INDEX(tblProducts[Rating],MATCH(C18,tblProducts[Rating Rank Key],0)) -> 5 | I18: Watercolour Gold Foil Textured Print Pillow Cover | J18: 0.43 | K18: High Discount | L18: 2.3 | M18: Poor
A19: 3 | B19: =INDEX(tblProducts[Product],MATCH(C19,tblProducts[Rating Rank Key],0)) -> Peacock Throw Pillow Cushion Case For Home Car | C19: =LARGE(tblProducts[Rating Rank Key],A19) -> 5.0000022 | D19: =INDEX(tblProducts[Rating],MATCH(C19,tblProducts[Rating Rank Key],0)) -> 5 | I19: Wrought Iron Bathroom Shelf Wall Mounted Free Punch Toilet Rack | J19: 0.43 | K19: High Discount | L19: 3 | M19: Average
A20: 4 | B20: =INDEX(tblProducts[Product],MATCH(C20,tblProducts[Rating Rank Key],0)) -> Anti-Skid Absorbent Insulation Coaster For Home Office | C20: =LARGE(tblProducts[Rating Rank Key],A20) -> 5.0000022 | D20: =INDEX(tblProducts[Rating],MATCH(C20,tblProducts[Rating Rank Key],0)) -> 5 | I20: 7-Piece Set Of Storage Bags, Travel Storage Bags, Shoe Bags | J20: 0.47 | K20: High Discount | L20: 2.2 | M20: Poor
A21: 5 | B21: =INDEX(tblProducts[Product],MATCH(C21,tblProducts[Rating Rank Key],0)) -> Konka Healty Electric Kettle, 24-Hour Heat Preservation,1.5L,800W, White | C21: =LARGE(tblProducts[Rating Rank Key],A21) -> 5.0000021 | D21: =INDEX(tblProducts[Rating],MATCH(C21,tblProducts[Rating Rank Key],0)) -> 5 | I21: Electric LED UV Mosquito Killer Lamp, Outdoor/Indoor Fly Killer Trap Light -USB | J21: 0.47 | K21: High Discount | L21: 2.1 | M21: Poor
A22: 6 | B22: =INDEX(tblProducts[Product],MATCH(C22,tblProducts[Rating Rank Key],0)) -> Bedroom Simple Floor Hanging Clothes Rack Single Pole Hat Rack - White | C22: =LARGE(tblProducts[Rating Rank Key],A22) -> 5.0000018 | D22: =INDEX(tblProducts[Rating],MATCH(C22,tblProducts[Rating Rank Key],0)) -> 5 | I22: Memory Foam Neck Pillow Cover, With Pillow Core - 50*30Cm | J22: 0.46 | K22: High Discount | L22: 3 | M22: Average
A23: 7 | B23: =INDEX(tblProducts[Product],MATCH(C23,tblProducts[Rating Rank Key],0)) -> DIY File Folder, Office Drawer File Holder, Pen Holder, Desktop Storage Rack | C23: =LARGE(tblProducts[Rating Rank Key],A23) -> 5.0000014 | D23: =INDEX(tblProducts[Rating],MATCH(C23,tblProducts[Rating Rank Key],0)) -> 5 | I23: Household Pineapple Peeler Peeler | J23: 0.49 | K23: High Discount | L23: 4 | M23: Average
A24: 8 | B24: =INDEX(tblProducts[Product],MATCH(C24,tblProducts[Rating Rank Key],0)) -> 40Cm Gold DIY Acrylic Wall Sticker Clock | C24: =LARGE(tblProducts[Rating Rank Key],A24) -> 4.8000121 | D24: =INDEX(tblProducts[Rating],MATCH(C24,tblProducts[Rating Rank Key],0)) -> 4.8 | I24: Wall-Mounted Sticker Punch-Free Plug Fixer | J24: 0.5 | K24: High Discount | L24: 2 | M24: Poor
A25: 9 | B25: =INDEX(tblProducts[Product],MATCH(C25,tblProducts[Rating Rank Key],0)) -> Lasa Folding Table Serving Stand | C25: =LARGE(tblProducts[Rating Rank Key],A25) -> 4.8000051 | D25: =INDEX(tblProducts[Rating],MATCH(C25,tblProducts[Rating Rank Key],0)) -> 4.8
A26: 10 | B26: =INDEX(tblProducts[Product],MATCH(C26,tblProducts[Rating Rank Key],0)) -> Portable Home Small Air Humidifier 3-Speed Fan - Green | C26: =LARGE(tblProducts[Rating Rank Key],A26) -> 4.8000051 | D26: =INDEX(tblProducts[Rating],MATCH(C26,tblProducts[Rating Rank Key],0)) -> 4.8
A29: Top 10 by Reviews
A30: Rank | B30: Product | C30: Sort Key | D30: Review Count
A31: 1 | B31: =INDEX(tblProducts[Product],MATCH(C31,tblProducts[Review Rank Key],0)) -> 120W Cordless Vacuum Cleaners Handheld Electric Vacuum Cleaner | C31: =LARGE(tblProducts[Review Rank Key],A31) -> 69.0028 | D31: =INDEX(tblProducts[Review],MATCH(C31,tblProducts[Review Rank Key],0)) -> 69
A32: 2 | B32: =INDEX(tblProducts[Product],MATCH(C32,tblProducts[Review Rank Key],0)) -> 137 Pieces Cake Decorating Tool Set Baking Supplies | C32: =LARGE(tblProducts[Review Rank Key],A32) -> 55.0046 | D32: =INDEX(tblProducts[Review],MATCH(C32,tblProducts[Review Rank Key],0)) -> 55
A33: 3 | B33: =INDEX(tblProducts[Product],MATCH(C33,tblProducts[Review Rank Key],0)) -> Electronic Digital Display Vernier Caliper | C33: =LARGE(tblProducts[Review Rank Key],A33) -> 49.0046 | D33: =INDEX(tblProducts[Review],MATCH(C33,tblProducts[Review Rank Key],0)) -> 49
A34: 4 | B34: =INDEX(tblProducts[Product],MATCH(C34,tblProducts[Review Rank Key],0)) -> 3D Waterproof EVA Plastic Shower Curtain 1.8*2Mtrs | C34: =LARGE(tblProducts[Review Rank Key],A34) -> 44.0046 | D34: =INDEX(tblProducts[Review],MATCH(C34,tblProducts[Review Rank Key],0)) -> 44
A35: 5 | B35: =INDEX(tblProducts[Product],MATCH(C35,tblProducts[Review Rank Key],0)) -> 100 Pcs Crochet Hook Tool Set Knitting Hook Set With Box | C35: =LARGE(tblProducts[Review Rank Key],A35) -> 39.0047 | D35: =INDEX(tblProducts[Review],MATCH(C35,tblProducts[Review Rank Key],0)) -> 39
A36: 6 | B36: =INDEX(tblProducts[Product],MATCH(C36,tblProducts[Review Rank Key],0)) -> Punch-Free Great Load Bearing Bathroom Storage Rack Wall Shelf-White | C36: =LARGE(tblProducts[Review Rank Key],A36) -> 36.0043 | D36: =INDEX(tblProducts[Review],MATCH(C36,tblProducts[Review Rank Key],0)) -> 36
A37: 7 | B37: =INDEX(tblProducts[Product],MATCH(C37,tblProducts[Review Rank Key],0)) -> 53 Pieces/Set Yarn Knitting Crochet Hooks With Bag - Pansies | C37: =LARGE(tblProducts[Review Rank Key],A37) -> 32.0045 | D37: =INDEX(tblProducts[Review],MATCH(C37,tblProducts[Review Rank Key],0)) -> 32
A38: 8 | B38: =INDEX(tblProducts[Product],MATCH(C38,tblProducts[Review Rank Key],0)) -> Portable Mini Cordless Car Vacuum Cleaner - Blue | C38: =LARGE(tblProducts[Review Rank Key],A38) -> 24.0046 | D38: =INDEX(tblProducts[Review],MATCH(C38,tblProducts[Review Rank Key],0)) -> 24
A39: 9 | B39: =INDEX(tblProducts[Product],MATCH(C39,tblProducts[Review Rank Key],0)) -> 53Pcs/Set Yarn Knitting Crochet Hooks With Bag - Fortune Cat | C39: =LARGE(tblProducts[Review Rank Key],A39) -> 20.0047 | D39: =INDEX(tblProducts[Review],MATCH(C39,tblProducts[Review Rank Key],0)) -> 20
A40: 10 | B40: =INDEX(tblProducts[Product],MATCH(C40,tblProducts[Review Rank Key],0)) -> 52 Pieces Cake Decorating Tool Set Gift Kit Baking Supplies | C40: =LARGE(tblProducts[Review Rank Key],A40) -> 20.0041 | D40: =INDEX(tblProducts[Review],MATCH(C40,tblProducts[Review Rank Key],0)) -> 20
A43: Top 10 by Discount
A44: Rank | B44: Product | C44: Sort Key | D44: Discount %
...

Sheet Pivot_Tables
A1: Discount Mix | H1: Top Products by Rating | L1: Top Products by Discount
H2: Row Labels | I2: Average of Rating | L2: Row Labels | M2: Average of Discount
A3: Row Labels | B3: Count of Product | H3: Classic Black Cat Cotton Hemp Pillow Case For Home Car | I3: 5 | L3: 6 In 1 Bottle Can Opener Multifunctional Easy Opener | M3: 0.64
A4: High Discount | B4: 65 | H4: Lasa Aluminum Folding Truck Hand Cart - 68Kg Max | I4: 5 | L4: Lasa Folding Table Serving Stand | M4: 0.55
A5: Low Discount | B5: 18 | H5: Konka Healty Electric Kettle, 24-Hour Heat Preservation,1.5L,800W, White | I5: 5 | L5: 5-Pcs Stainless Steel Cooking Pot Set With Steamed Slices | M5: 0.55
A6: Medium Discount | B6: 32 | H6: Anti-Skid Absorbent Insulation Coaster For Home Office | I6: 5 | L6: Creative Owl Shape Keychain Black | M6: 0.55
A7: Grand Total | B7: 115 | H7: Peacock Throw Pillow Cushion Case For Home Car | I7: 5 | L7: Lasa 3 Tier Bamboo Shoe Bench Storage Shelf | M7: 0.54
H8: Bedroom Simple Floor Hanging Clothes Rack Single Pole Hat Rack - White | I8: 5 | L8: Mythco 120Cob Solar Wall Ligt With Motion Sensor And Remote Control 3 Modes | M8: 0.54
H9: DIY File Folder, Office Drawer File Holder, Pen Holder, Desktop Storage Rack | I9: 5 | L9: Classic Black Cat Cotton Hemp Pillow Case For Home Car | M9: 0.53
H10: Lasa Folding Table Serving Stand | I10: 4.8 | L10: 3Pcs Single Head Knitting Crochet Sweater Needle Set | M10: 0.53
H11: Portable Home Small Air Humidifier 3-Speed Fan - Green | I11: 4.8 | L11: Exfoliate And Exfoliate Face Towel - Black | M11: 0.52
H12: 40Cm Gold DIY Acrylic Wall Sticker Clock | I12: 4.8 | L12: Intelligent LED Body Sensor Wireless Lighting Night Light USB | M12: 0.52
A13: Rating Mix | H13: Grand Total | I13: 4.94 | L13: Grand Total | M13: 0.54727273
A14: Row Labels | B14: Count of Product
A15: Average | B15: 26
A16: Excellent | B16: 19 | H16: Top Products by Reviews | L16: Discount vs Rating Cross-tab
A17: Missing | B17: 58 | H17: Row Labels | I17: Sum of Review | L17: Count of Product | M17: Column Labels
A18: Poor | B18: 12 | H18: 120W Cordless Vacuum Cleaners Handheld Electric Vacuum Cleaner | I18: 69 | L18: Row Labels | M18: Average | N18: Excellent | O18: Missing | P18: Poor | Q18: Grand Total
A19: Grand Total | B19: 115 | H19: 137 Pieces Cake Decorating Tool Set Baking Supplies | I19: 55 | L19: High Discount | M19: 12 | N19: 8 | O19: 35 | P19: 10 | Q19: 65
H20: Electronic Digital Display Vernier Caliper | I20: 49 | L20: Low Discount | M20: 2 | N20: 1 | O20: 14 | P20: 1 | Q20: 18
H21: 3D Waterproof EVA Plastic Shower Curtain 1.8*2Mtrs | I21: 44 | L21: Medium Discount | M21: 12 | N21: 10 | O21: 9 | P21: 1 | Q21: 32
H22: 100 Pcs Crochet Hook Tool Set Knitting Hook Set With Box | I22: 39 | L22: Grand Total | M22: 26 | N22: 19 | O22: 58 | P22: 12 | Q22: 115
A23: Engagement by Discount | H23: Punch-Free Great Load Bearing Bathroom Storage Rack Wall Shelf-White | I23: 36
A24: Row Labels | B24: Average of Review | H24: 53 Pieces/Set Yarn Knitting Crochet Hooks With Bag - Pansies | I24: 32
A25: High Discount | B25: 11.133333 | H25: Portable Mini Cordless Car Vacuum Cleaner - Blue | I25: 24
